<Document accessor="public" category="Function" name="GetFailure"><summary>Returns the current exception.</summary><returns>The current exception. It could cause by the Workflow script that creates this coroutine, or by calling <symbol name="Resume" docId="vl::reflection::description::ICoroutine::Resume@void(bool, ::vl::Ptr&lt;::vl::reflection::description::CoroutineResult&gt;)"/> when this coroutine is in an inappropriate state.</returns><signature><![CDATA[Ptr<IValueException> GetFailure(
);
]]></signature><seealsos><symbol name="Ptr" docId="vl::Ptr"/><symbol name="IValueException"/></seealsos></Document>